Workbook

Sheet Ofícios
A1: CONTROLE DE OFÍCIO SIMPLES - 2025
A2: Nº | B2: Data | C2: Assunto | D2: Destino | E2: CC | F2: Responsável
A4: 1700 | B4: 45904 | C4: Solicita produção de cards sobre a disponibilização dos ônibus nos dias 8 e 11 de setembro | D4: Setor de Comunicação | F4: Raphael
A5: 1701 | B5: 45904 | C5: Solicita reserva do auditório da prefeitura para receber equipe da Escola Aprendiz de Marinheiro | D5: Gabinete | F5: Raphael
A6: 1702 | B6: 45904 | C6: Solicita pagamento da conta NEOENERGIA - Escola Madre Virgínia | D6: Secretaria de Finanças | F6: Sebastião
A7: 1703 | B7: 45904 | C7: Solicita Contratação de Monitores para ônibus que fazem as rotas na Zona Rural | D7: Gabinete | F7: Raphael
A8: 1704 | B8: 45904 | C8: Aquisição de Insumos para Almoço do dia 11 de setembro | D8: Secretaria de Governo | F8: Paula Karina
A9: 1705 | B9: 45904 | C9: Resposta ao Ofício nº 163/2025 | D9: SINDPROFM | F9: Raphael
A10: 1706 | B10: 45904 | C10: Solicita retirada de materiais de limpeza - ARTLIMP | D10: Setor de Compras | F10: Thayza
A11: 1707 | B11: 45904 | C11: Encaminha frequência da segunda quinzena de Agosto | D11: RH | F11: Lara
A12: 1708 | B12: 45904 | C12: Encaminha Nota Fiscal Pablo Luis Martins | D12: Secretaria de Finanças | F12: Raphael
A13: 1709 | B13: 45905 | C13: Encaminha DFD - Kits Escolares 2026 | D13: Secretaria de Administração | E13: Setor de Licitação | F13: Sebastião
A14: 1710 | B14: 45905 | C14: Detetização da Escola | D14: Secretaria de Governo | F14: Raphael
A15: 1711 | B15: 45905 | C15: Aluguel de Imovel Luna Filho Loja Maçonica | D15: Secretaria de Finanças | E15: Secretaria de Administração | F15: Thayza
A16: 1712 | B16: 45905 | C16: Resposta ao MP Oficio 02207.000.224/2025-0002 | D16: Ministério Publico PE | F16: Raimunda
A17: 1713 | B17: 45905 | C17: Solicita contrato de Sinthya Jeronimo da Silva e encaminha docs | D17: Gabinete | F17: Raphael
A18: 1714 | B18: 45905 | C18: Aluguel de Imovel Rancho do Himalaia | D18: Secretaria de Finanças | E18: Secretaria de Administração | F18: Thayza
A19: 1715 | B19: 45905 | C19: Aluguel de Imovel Sao Joaquim Caraúbas | D19: Secretaria de Finanças | E19: Secretaria de Administração | F19: Thayza
A20: 1716 | B20: 45905 | C20: Aluguel Imovel Madre Virginia | D20: Secretaria de Finanças | E20: Secretaria de Administração | F20: Thayza
A21: 1717 | B21: 45905 | C21: Aluguel de Imovel CEI Santa' Ana Olho Dágua | D21: Secretaria de Finanças | E21: Secretaria de Administração | F21: Thayza
A22: 1718 | B22: 45905 | C22: Aluguel de Imovel Deposito de Merenda | D22: Secretaria de Finanças | E22: Secretaria de Administração | F22: Thayza
A23: 1719 | B23: 45905 | C23: Encaminha Requerimento de Férias | D23: RH | F23: Lara
A24: 1720 | B24: 45905 | C24: Aluguel de Imovel Quadra Carauba | D24: Secretaria de Finanças | E24: Secretaria de Administração | F24: Thayza
A25: 1721 | B25: 45905 | C25: Aluguel de Imovel Casa Rosa | D25: Secretaria de Finanças | E25: Secretaria de Administração | F25: Thayza
A26: 1722 | B26: 45905 | C26: Aluguel de Imovel SEE | D26: Secretaria de Finanças | E26: Secretaria de Administração | F26: Thayza
A27: 1723 | B27: 45905 | C27: Aluguel de Imovel CEI SANTANA | D27: Secretaria de Finanças | E27: Secretaria de Administração | F27: Thayza
A28: 1724 | B28: 45905 | C28: Aluguel de Imovel CEI PETRIBU | D28: Secretaria de Finanças | E28: Secretaria de Administração | F28: Thayza
A29: 1725 | B29: 45905 | C29: Aluguel Imovel Programa Amor | D29: Secretaria de Finanças | E29: Secretaria de Administração | F29: Thayza
A30: 1726 | B30: 45905 | C30: Aluguel Imovel PIO X | D30: Secretaria de Finanças | E30: Secretaria de Administração | F30: Thayza
A31: 1727 | B31: 45905 | C31: Aluguel Nova Santa Cruz | D31: Secretaria de Finanças | E31: Secretaria de Administração | F31: Thayza
A32: 1728 | B32: 45905 | C32: Encaminhamento de planilha de licença prêmio e solicitação de portarias | D32: RH | F32: Lara
A33: 1729 | B33: 45905 | C33: Encaminha Nota Fiscal RECICOM | D33: Secretaria de Finanças | F33: Sebastião
A34: 1730 | B34: 45905 | C34: Encaminha Nota Fiscal BIZ SOLUÇÕES | D34: Secretaria de Finanças | F34: Sebastião
A35: 1731 | B35: 45905 | C35: Encaminha Nota Fiscal MP3 Distribuidora | D35: Secretaria de Finanças | F35: Sebastião
A36: 1732 | B36: 45905 | C36: Encaminha Nota Fiscal Ezata Mercantil | D36: Secretaria de Finanças | F36: Sebastião
A37: 1733 | B37: 45908 | C37: Encaminha Nota Fiscal Adriana da Silva Ferreira Delivery | D37: Secretaria de Finanças | F37: Sebastião
A38: 1734 | B38: 45909 | C38: Encaminha Nota Fiscal - Aluguel e serviços de refrigeração - Helinberg | D38: Secretaria de Finanças | F38: Sebastião
A39: 1735 | B39: 45909 | C39: Solicita contrato de Rebeca Karine de Souza Costa Correia Melo e encaminha docs | D39: Gabinete | F39: Raphael
A40: 1736 | B40: 45909 | C40: Resposta ao MP Oficio 02208.000.321/2025-0002 | D40: Ministério Publico PE | F40: Thayza
A41: 1737 | B41: 45909 | C41: Encaminha Nota Fiscal - Carmel - Compra de Corda desfile | D41: Secretaria de Finanças | F41: Sebastião
...

Sheet < 1700
A1: CONTROLE DE OFÍCIO SIMPLES - 2025
A2: Nº | B2: Data | C2: Assunto | D2: Destino | E2: CC | F2: Responsável
A3: 1 | B3: 45660 | C3: RELATORIO DE MOBILIÁRIO | D3: Secretaria de Planejamento e Gestão
A4: 2 | B4: 45660 | C4: INFORMAÇÕES SOBRE O PETE | D4: Setor de Transportes
A5: 3 | B5: 45665 | C5: CALENDÁRIO ESCOLAR | D5: SINDPROFM
A6: 4 | B6: 45665 | C6: TERÇO DE FÉRIAS E FÉRIAS | D6: RH
A7: 5 | B7: 45665 | C7: RELAÇÃO DE CARGOS DA SEE | D7: Gabinete
A8: 6 | B8: 45665 | C8: LICENÇA PRÊMIO | D8: RH
A9: 7 | B9: 45665 | C9: ATIVAÇÃO DE CONTAS CORRENTES
A10: 8 | B10: 45665 | C10: RELAÇÃO DE NESSECIDADE DE CONTRATO | D10: Gabinete
A11: 9 | B11: 45666 | C11: TERÇO DE FÉRIAS E FÉRIAS | D11: RH
A12: 10 | B12: 45666 | C12: APOSENTARIA DE SERVIDORA | D12: RH
A13: 11 | B13: 45667 | C13: SOLICITAÇÃO DE VISTORIA SEE | D13: Secretaria de Infraestrutura
A14: 12 | B14: 45667 | C14: COMPRA DE AMTERIAL | D14: Gabinete
A15: 13 | B15: 45667 | C15: ENCAMINHAR DOCUMENTAÇÃO PESSOAL | D15: Gabinete
A16: 14 | B16: 45670 | C16: SOLICITAÇÃO DE VISTORIA | D16: Secretaria de Infraestrutura
A17: 15 | B17: 45670 | C17: SOLICITAÇÃO DE VISTORIA PRÉDIO CEI PETRIBÚ | D17: Secretaria de Infraestrutura
A18: 16 | B18: 45670 | C18: SOLICITAR ESTUDO TÉCNIVO - PERFURAÇÃO DE POÇO | D18: Secretaria de Infraestrutura
A19: 17 | B19: 45670 | C19: SOLICITAR REPAROS NAS SALAS ESC. IRINEU DE PONTES | D19: Secretaria de Infraestrutura
A20: 18 | B20: 45670 | C20: ENCAMINHAR DOCUMENTAÇÃO PESSOAL | D20: Gabinete
A21: 19 | B21: 45670 | C21: ALTERAÇÃO DE CALENDÁRIO 2025
A22: 20 | B22: 45670 | C22: ADICIONAL DE PRODUTIVIDADE | D22: RH
A23: 21 | B23: 45670 | C23: SOLICITAÇÃO MOBILIÁRIO ESCOLAR | D23: Setor de Licitação
A24: 22 | B24: 45671 | C24: SOLICITAÇÃO DE REFORMA NA CRECHE ZITE LAPA | D24: Secretaria de Infraestrutura
A25: 23 | B25: 45672 | C25: INFORMAÇÃO DA BIBLIOTECA | D25: Secretaria de Infraestrutura
A26: 24 | B26: 45672 | C26: ESTRUTURA DA SEE | D26: Gabinete
A27: 25 | B27: 45672 | C27: INFORMAR NOVO ARTICULADOR CNCA
A28: 26 | B28: 45672 | C28: INFORMAR NOVO ARTICULADOR CNCA
A29: 27 | B29: 45672 | C29: VISTORIA NA ESCOLA SÃO JOAQUIM ( VILA CARAUBA) | D29: Secretaria de Infraestrutura
A30: 28 | B30: 45672 | C30: ENCAMINHAR DOCUMENTAÇÃO PESSOAL | D30: Gabinete
A31: 29 | B31: 45673 | C31: RENOVAÇÃO DE CONTRATO SICAP | D31: Setor de Licitação
A32: 30 | B32: 45673 | C32: SOLICITAÇÕES EMERGENCIAIS | D32: Secretaria de Infraestrutura
A33: 31 | B33: 45673 | C33: ENCAMINHAR DOCUMENTAÇÃO PESSOAL | D33: Gabinete
A34: 32 | B34: 45677 | C34: INFORMAÇÃO PESSOAL SEDUC | D34: Gabinete
A35: 33 | B35: 45674 | C35: TRANSPORTE PARA VITORIA DE SANTO ANTÃO | D35: Gabinete
A36: 34 | B36: 45677 | C36: LICENÇA PRÊMIO (MARIA VERONICA) | D36: RH
A37: 35 | B37: 45677 | C37: LICENÇA PRÊMIO (MARIA VERNICA) | D37: RH
A38: 36 | B38: 45677 | C38: REMOÇÃO DE BENS EM DESUSO | D38: Secretaria de Infraestrutura
A39: 37 | B39: 45677 | C39: TERÇO DE FPERIAS E FÉRIAS | D39: RH
A40: 38 | B40: 45677 | C40: IMPRESSÃO DE CARTEIRAS TRANSPORTE | D40: Setor de Licitação
...

Sheet Ofícios Circulares
A1: CONTROLE DE OFÍCIO CIRCULARES - 2025
A2: Nº | B2: Data | C2: Assunto | D2: Destinos | E2: Responsável
A3: 25 | B3: 09/04/2025 | C3: Convite para evento com Escola de Aprendiz de Marinheiro no Auditório da Prefeitura | D3: Escolas de Carpina | E3: Raphael
A4: 26 | B4: 06/10/2025 | C4: Expedientes dia 08 e 12 | D4: Escolas Municipais | E4: Raphael
A5: 27 | B5: 06/10/2025 | C5: Comunica sobre a Transferência dos feriados dos dias 15 e 28 | D5: Escolas Municipais | E5: Raphael
A6: 28 | B6: 07/10/2025 | C6: Solicita o uso de detectores de metais nas escolas | D6: Escolas Municipais | E6: Ana Christine
A7: 29 | B7: 08/10/2025 | C7: Informa a data de aplicação das provas do SAEB | D7: Escolas Municipais | E7: Raimunda
A8: 30
A9: 31
A10: 32
A11: 33
A12: 34
A13: 35
A14: 36
A15: 37
A16: 38
A17: 39
A18: 40
A19: 41
... A478: 500

Sheet Dados
A2: Destinos | C2: Responsáveis
A3: Gabinete | B3: Diogo Prado | C3: Ana Christine
A4: RH | B4: Kassia Vera Cruz Zamorano Grassi | C4: Ana Paula
A5: Secretaria da Mulher | B5: Izaura Pessoa | C5: Almir
A6: Secretaria de Administração | B6: Izaura Pessoa | C6: Edson
A7: Secretaria de Cultura, Turismo e Lazer | B7: Marta Guerra | C7: Fabrício
A8: Secretaria de Desenvolvimento Econômico, Indústria e Comércio | B8: Rafaela Britto | C8: Flávia
A9: Secretaria de Desenvolvimento Social, Criança e Juventude | B9: Marcelo Pascoal | C9: Lara
A10: Secretaria de Educação e Esportes | B10: Rosejara Ramos | C10: Luzinete
A11: Secretaria de Finanças | B11: Lucas Israel | C11: Luzivânia
A12: Secretaria de Infraestrutura | B12: Tiago Grassi | C12: Paula Karina
A13: Secretaria de Meio Ambiente e da Causa Animal | B13: Giovanni José | C13: Raimunda
A14: Secretaria de Planejamento e Gestão | B14: Marcelo Gomes | C14: Raphael
... A17: Setor de Comunicação | B17: Stefhane Hellem | C17: Tallita
A18: Escolas de Carpina | C18: Thayza
A19: Escolas Estaduais | C19: Tiago
A20: Escolas Municipais | C20: Helse Montarroyos
A21: Secretaria de Governo | B21: Roberval Araújo
A22: Setor de Compras | B22: Rafael Araújo
A23: Wiguivaldo Patriota Santos
A24: Ministério Publico PE
A25: Gerencia de TI
A26: Controladoria Geral Municipio de Carpina
A27: Autarquia de Trânsito | B27: Jorge Lapa
A28: Secretaria de Serviços Urbanos | B28: Rodrigo Pires
A29: Escola São José
A30: Setor de Transportes | B30: Silvio Mendes
A31: Movimento Reflorestando Carpina
A32: Policia Militar de Carpina
A33: Secretario de Serviços Urbanos
A34: Secretaria Executiva de Administração
A35: Procuradoria do Município
A36: Ministerio Público Federal
A37: Escola Pio X
A38: Escola Eliane Carneiro
A39: Escola Santa Ana
A40: Escola Mínima de Florestinha
A41: Centro de Referência Especializado de Assistência Social - CREAS
A42: Presidente CAE/CME
... A59: Diretoria de Transportes

Sheet Dashboard
B1: Cadastrados <1700 | C1: =COUNTA('< 1700'!B3:B1701) -> 592 | D1: Cadastrados total | E1: =COUNTA('Ofícios'!$B$4:$B$1304) -> 621
B2: Faltando: | C2: =1700-C1 -> 1108 | D2: Não vazias | E2: =E1+C1 -> 1213
B4: Total de ofícios: | H4: Total de ofícios registrados: | M4: Total de ofícios a serem registrados:
B5: =C2+E2 -> 2321 | H5: =E2 -> 1213 | M5: =C2 -> 1108
B11: Total de ofícios por responsáveis: | H11: Total de ofícios por meses:
B12: =Dados!C3 -> Ana Christine | F12: =COUNTIF('Ofícios'!F:F, B12) -> 2 | H12: Janeiro | I12: =SUMPRODUCT((MONTH('Ofícios'!B4:B1001)=1)*(ISNUMBER('Ofícios'!B4:B1001))) -> #VALUE!
B13: =Dados!C4 -> Ana Paula | F13: =COUNTIF('Ofícios'!F:F, B13) -> 0 | H13: Fevereiro | I13: =SUMPRODUCT((MONTH('Ofícios'!B4:B1001)=2)*(ISNUMBER('Ofícios'!B4:B1001))) -> #VALUE!
B14: =Dados!C5 -> Almir | F14: =COUNTIF('Ofícios'!F:F, B14) -> 66 | H14: Março | I14: =SUMPRODUCT((MONTH('Ofícios'!B4:B1001)=3)*(ISNUMBER('Ofícios'!B4:B1001))) -> #VALUE!
B15: =Dados!C6 -> Edson | F15: =COUNTIF('Ofícios'!F:F, B15) -> 0 | H15: Abril | I15: =SUMPRODUCT((MONTH('Ofícios'!B4:B1001)=4)*(ISNUMBER('Ofícios'!B4:B1001))) -> #VALUE!
B16: =Dados!C7 -> Fabrício | F16: =COUNTIF('Ofícios'!F:F, B16) -> 0 | H16: Maio | I16: =SUMPRODUCT((MONTH('Ofícios'!B4:B1001)=5)*(ISNUMBER('Ofícios'!B4:B1001))) -> #VALUE!
B17: =Dados!C8 -> Flávia | F17: =COUNTIF('Ofícios'!F:F, B17) -> 0 | H17: Junho | I17: =SUMPRODUCT((MONTH('Ofícios'!B4:B1001)=6)*(ISNUMBER('Ofícios'!B4:B1001))) -> #VALUE!
B18: =Dados!C9 -> Lara | F18: =COUNTIF('Ofícios'!F:F, B18) -> 40 | H18: Julho | I18: =SUMPRODUCT((MONTH('Ofícios'!B4:B1001)=7)*(ISNUMBER('Ofícios'!B4:B1001))) -> #VALUE!
B19: =Dados!C10 -> Luzinete | F19: =COUNTIF('Ofícios'!F:F, B19) -> 6 | H19: Agosto | I19: =SUMPRODUCT((MONTH('Ofícios'!B4:B1001)=8)*(ISNUMBER('Ofícios'!B4:B1001))) -> #VALUE!
B20: =Dados!C11 -> Luzivânia | F20: =COUNTIF('Ofícios'!F:F, B20) -> 0 | H20: Setembro | I20: =SUMPRODUCT((MONTH('Ofícios'!B4:B1001)=9)*(ISNUMBER('Ofícios'!B4:B1001))) -> #VALUE!
B21: =Dados!C12 -> Paula Karina | F21: =COUNTIF('Ofícios'!F:F, B21) -> 13 | H21: Outubro | I21: =SUMPRODUCT((MONTH('Ofícios'!B4:B1001)=10)*(ISNUMBER('Ofícios'!B4:B1001))) -> #VALUE!
B22: =Dados!C13 -> Raimunda | F22: =COUNTIF('Ofícios'!F:F, B22) -> 5 | H22: Novembro | I22: =SUMPRODUCT((MONTH('Ofícios'!B4:B1001)=11)*(ISNUMBER('Ofícios'!B4:B1001))) -> #VALUE!
B23: =Dados!C14 -> Raphael | F23: =COUNTIF('Ofícios'!F:F, B23) -> 183 | H23: Dezembro | I23: =SUMPRODUCT((MONTH('Ofícios'!B4:B1001)=12)*(ISNUMBER('Ofícios'!B4:B1001))) -> #VALUE!
B24: =Dados!C15 -> Rúbia | F24: =COUNTIF('Ofícios'!F:F, B24) -> 2
B25: =Dados!C16 -> Sebastião | F25: =COUNTIF('Ofícios'!F:F, B25) -> 103
B26: =Dados!C17 -> Tallita | F26: =COUNTIF('Ofícios'!F:F, B26) -> 10
B27: =Dados!C18 -> Thayza | F27: =COUNTIF('Ofícios'!F:F, B27) -> 171
B28: =Dados!C19 -> Tiago | F28: =COUNTIF('Ofícios'!F:F, B28) -> 0
B29: =Dados!C20 -> Helse Montarroyos | F29: =COUNTIF('Ofícios'!F:F, B29) -> 19
